之前演示过，如果Observable内部发出错误，只会进入error回调
```typescript
of(1, 2, 3, 4, 5).pipe(
  map(n => {
    if (n === 4) {
      throw new Error('four err!');
    }
    return n;
  })
).subscribe(
  x => console.log(x),
  error => console.error('err', error),
  () => console.log('complete')
);
```

可以通过一些操作符改变这行为：

## catchError

- 无视错误，返回一个新的Observable
```typescript
of(1, 2, 3, 4, 5).pipe(
  map(n => {
    if (n === 4) {
      throw new Error('four err!');
    }
    return n;
  }),
  catchError(err => of('I', 'II', 'III', 'IV', 'V')),
).subscribe(
  x => console.log(x),
  error => console.error('err', error), // 不会走这里
  () => console.log('complete')
);
```

- 重试错误
```typescript
of(1, 2, 3, 4, 5).pipe(
  map(n => {
    if (n === 4) {
      throw new Error('four err!');
    }
    return n;
  }),
  catchError((err, caught) => caught),
  take(30),
).subscribe(x => console.log(x));
```

- 抛出一个新的错误
```typescript
of(1, 2, 3, 4, 5).pipe(
  map(n => {
    if (n === 4) {
      throw new Error('four err!');
    }
    return n;
  }),
  catchError(err => {
    throw new Error('error in source. Details: ' + err);
  }),
)
  .subscribe(
    x => console.log(x),
    err => console.error('err ', err),
    () => console.log('complete') // 不会走这里
  );
```


## retry
发生错误后重试指定次数
```typescript
const source = interval(1000);
  const example = source.pipe(
    mergeMap(val => {
      if (val > 5){
        return throwError('Error!');
      }
      return of(val);
    }),
    // 重试两次
    retry(2)
  );

  const subscribe = example.subscribe({
    next: val => console.log(val),
    error: val => console.error('err ', `${val}: Retried 2 times then quit!`)
  });
```

## retryWhen
发生错误后 自定义重试策略，参数是个回调函数，返回Observable
```typescript
const source = interval(1000);
const example = source.pipe(
  map(val => {
    if (val > 5) {
      // 错误将由 retryWhen 接收
      throw val;
    }
    return val;
  }),
  retryWhen(errors =>
    errors.pipe(
      // 输出错误信息
      tap(val => console.log(`Value ${val} 太大了!`)),
      // 3秒后重试
      delay(3000)
    )
  )
);
const subscribe = example.subscribe(
  val => console.log(val),
  error => console.error('err ', error)
);
```
